<?xml version="1.0" ?>
<!-- =================================================================================== -->
<!-- |    This document was autogenerated by xacro from /home/chalmers/gym-gazebo/gym_gazebo/envs/installation/catkin_ws/src/drcsim/irobot_hand_description/robots/irobot_hand_on_box.urdf.xacro | -->
<!-- |    EDITING THIS FILE BY HAND IS NOT RECOMMENDED                                 | -->
<!-- =================================================================================== -->
<robot name="atlas" xmlns:xacro="http://www.ros.org/wiki/xacro">
  <!-- roslaunch urdf_tutorial display.launch model:=handle.urdf gui:=True -->
  <!-- rosrun xacro xacro.py handle_urdf.xacro > handle.urdf -->
  <!-- tip: use measurements from solid to find the origins and length -->
  <!--${0.5*flex_joint_length/flex_joint_steps}-->
  <!-- Simplified collisions for the base_rotation_links on fingers 0 and 1 -->
  <!-- Simplified collisions for the proximal_link on all fingers -->
  <!-- Simplified collisions for the distal_link on all fingers -->
  <!-- base -->
  <link name="base">
    <inertial>
      <mass value="0.1"/>
      <origin rpy="0 0 0" xyz="0 0 0.25"/>
      <inertia ixx="0.01" ixy="0" ixz="0" iyy="0.01" iyz="0" izz="0.01"/>
    </inertial>
    <visual>
      <origin rpy="0 0 0" xyz="0 0 0.25"/>
      <geometry>
        <box size="0.5 0.5 0.5"/>
      </geometry>
    </visual>
    <collision>
      <origin rpy="0 0 0" xyz="0 0 0.25"/>
      <geometry>
        <box size="0.5 0.5 0.5"/>
      </geometry>
    </collision>
  </link>
  <link name="left_finger[0]/flexible_link_1">
    <inertial>
      <mass value="0.00058"/>
      <!-- gazebo -> cad mapping
           x -> y
           y -> z
           z -> x
      -->
      <origin rpy="-1.57 -1.57 0" xyz="0 0 0"/>
      <inertia ixx="8.8101e-8" ixy="0" ixz="0.0" iyy="4.09812e-08" iyz="0.0" izz="5.31842e-08"/>
    </inertial>
    <collision>
      <geometry>
        <box size=".014 0.00792 .006"/>
      </geometry>
      <origin rpy="1.57 0 0" xyz="0 0 0"/>
    </collision>
    <visual>
      <geometry>
        <box size=".014 0.00792 .006"/>
      </geometry>
      <origin rpy="1.57 0 0" xyz="0 0 0"/>
      <material name="darkgray">
        <color rgba="0.2 0.2 0.2 1"/>
      </material>
    </visual>
  </link>
  <link name="left_finger[0]/flexible_link_2">
    <inertial>
      <mass value="0.00058"/>
      <!-- gazebo -> cad mapping
           x -> y
           y -> z
           z -> x
      -->
      <origin rpy="-1.57 -1.57 0" xyz="0 0 0"/>
      <inertia ixx="8.8101e-8" ixy="0" ixz="0.0" iyy="4.09812e-08" iyz="0.0" izz="5.31842e-08"/>
    </inertial>
    <collision>
      <geometry>
        <box size=".014 0.00792 .006"/>
      </geometry>
      <origin rpy="1.57 0 0" xyz="0 0 0"/>
    </collision>
    <visual>
      <geometry>
        <box size=".014 0.00792 .006"/>
      </geometry>
      <origin rpy="1.57 0 0" xyz="0 0 0"/>
      <material name="darkgray">
        <color rgba="0.2 0.2 0.2 1"/>
      </material>
    </visual>
  </link>
  <!-- only up to flex_joint_steps
  <xacro:flex_link side="${side}" finger_id="0" link_id="3"/>
  <xacro:flex_link side="${side}" finger_id="0" link_id="4"/>
  <xacro:flex_link side="${side}" finger_id="0" link_id="5"/>
  <xacro:flex_link side="${side}" finger_id="0" link_id="6"/>
  <xacro:flex_link side="${side}" finger_id="0" link_id="7"/>
  <xacro:flex_link side="${side}" finger_id="0" link_id="8"/>
  <xacro:flex_link side="${side}" finger_id="0" link_id="9"/>
  -->
  <gazebo reference="left_finger[0]/flexible_joint_flex_from_1_to_2">
    <implicitSpringDamper>1</implicitSpringDamper>
  </gazebo>
  <joint name="left_finger[0]/flexible_joint_flex_from_1_to_2" type="revolute">
    <parent link="left_finger[0]/flexible_link_1"/>
    <child link="left_finger[0]/flexible_link_hidden_between_1_and_2"/>
    <origin xyz="0 0 0.008"/>
    <axis xyz="-1 0 0"/>
    <limit effort="1000.0" lower="0.0" upper="1.57" velocity="0.5"/>
  </joint>
  <link name="left_finger[0]/flexible_link_hidden_between_1_and_2">
    <inertial>
      <mass value="0.00058"/>
      <!-- gazebo -> cad mapping
           x -> y
           y -> z
           z -> x
      -->
      <origin rpy="-1.57 -1.57 0" xyz="0 0 0"/>
      <inertia ixx="8.8101e-8" ixy="0" ixz="0.0" iyy="4.09812e-08" iyz="0.0" izz="5.31842e-08"/>
    </inertial>
    <collision>
      <geometry>
        <box size="0 0 0"/>
      </geometry>
      <origin rpy="0 0 0" xyz="0 0 0"/>
    </collision>
    <visual>
      <geometry>
        <box size="0 0 0"/>
      </geometry>
      <origin rpy="0 0 0" xyz="0 0 0"/>
    </visual>
  </link>
  <gazebo reference="left_finger[0]/flexible_joint_twist_from_1_to_2">
    <implicitSpringDamper>1</implicitSpringDamper>
  </gazebo>
  <joint name="left_finger[0]/flexible_joint_twist_from_1_to_2" type="revolute">
    <parent link="left_finger[0]/flexible_link_hidden_between_1_and_2"/>
    <child link="left_finger[0]/flexible_link_2"/>
    <origin xyz="0 0 0"/>
    <axis xyz="0 0 1"/>
    <limit effort="1000.0" lower="0.0" upper="1.57" velocity="0.5"/>
  </joint>
  <!-- only up to flex_joint_steps
  <xacro:flex_joint side="${side}" finger_id="0" link_from="2" link_to="3"/>
  <xacro:flex_joint side="${side}" finger_id="0" link_from="3" link_to="4"/>
  <xacro:flex_joint side="${side}" finger_id="0" link_from="4" link_to="5"/>
  <xacro:flex_joint side="${side}" finger_id="0" link_from="5" link_to="6"/>
  <xacro:flex_joint side="${side}" finger_id="0" link_from="6" link_to="7"/>
  <xacro:flex_joint side="${side}" finger_id="0" link_from="7" link_to="8"/>
  <xacro:flex_joint side="${side}" finger_id="0" link_from="8" link_to="9"/>
  -->
  <!-- make a connection between proximal to flexible-->
  <gazebo reference="left_finger[0]/flexible_joint_flex_from_proximal_to_1">
    <implicitSpringDamper>1</implicitSpringDamper>
  </gazebo>
  <joint name="left_finger[0]/flexible_joint_flex_from_proximal_to_1" type="revolute">
    <parent link="left_finger[0]/proximal_link"/>
    <child link="left_finger[0]/flexible_link_hidden_between_proximal_link_and_1"/>
    <origin xyz="0 0 0.065"/>
    <axis xyz="-1 0 0"/>
    <limit effort="1000.0" lower="0.0" upper="1.57" velocity="0.5"/>
  </joint>
  <link name="left_finger[0]/flexible_link_hidden_between_proximal_link_and_1">
    <inertial>
      <!-- <mass value="${0.0029 / 19}"/> -->
      <mass value="0.00058"/>
      <!-- gazebo -> cad mapping
           x -> y
           y -> z
           z -> x
      -->
      <origin rpy="-1.57 -1.57 0" xyz="0 0 0"/>
      <inertia ixx="8.8101e-8" ixy="0" ixz="0.0" iyy="4.09812e-08" iyz="0.0" izz="5.31842e-08"/>
    </inertial>
    <collision>
      <geometry>
        <box size="0 0 0"/>
      </geometry>
      <origin rpy="0 0 0" xyz="0 0 0"/>
    </collision>
    <visual>
      <geometry>
        <box size="0 0 0"/>
      </geometry>
      <origin rpy="0 0 0" xyz="0 0 0"/>
    </visual>
  </link>
  <gazebo reference="left_finger[0]/flexible_joint_twist_from_proximal_to_1">
    <implicitSpringDamper>1</implicitSpringDamper>
  </gazebo>
  <joint name="left_finger[0]/flexible_joint_twist_from_proximal_to_1" type="revolute">
    <parent link="left_finger[0]/flexible_link_hidden_between_proximal_link_and_1"/>
    <child link="left_finger[0]/flexible_link_1"/>
    <origin xyz="0 0 0"/>
    <axis xyz="0 0 1"/>
    <limit effort="1000.0" lower="0.0" upper="1.57" velocity="0.5"/>
  </joint>
  <!-- make a connection between flexible to distal-->
  <gazebo reference="left_finger[0]/flexible_joint_flex_from_2_to_distal">
    <implicitSpringDamper>1</implicitSpringDamper>
  </gazebo>
  <joint name="left_finger[0]/flexible_joint_flex_from_2_to_distal" type="revolute">
    <parent link="left_finger[0]/flexible_link_2"/>
    <child link="left_finger[0]/flexible_link_hidden_between_2_and_distal_link"/>
    <origin xyz="0 0 0.005"/>
    <axis xyz="-1 0 0"/>
    <limit effort="1000.0" lower="0.0" upper="1.57" velocity="0.5"/>
  </joint>
  <link name="left_finger[0]/flexible_link_hidden_between_2_and_distal_link">
    <inertial>
      <mass value="0.00058"/>
      <!-- gazebo -> cad mapping
           x -> y
           y -> z
           z -> x
      -->
      <origin rpy="-1.57 -1.57 0" xyz="0 0 0"/>
      <inertia ixx="8.8101e-8" ixy="0" ixz="0.0" iyy="4.09812e-08" iyz="0.0" izz="5.31842e-08"/>
    </inertial>
    <collision>
      <geometry>
        <box size="0 0 0"/>
      </geometry>
      <origin rpy="0 0 0" xyz="0 0 0"/>
    </collision>
    <visual>
      <geometry>
        <box size="0 0 0"/>
      </geometry>
      <origin rpy="0 0 0" xyz="0 0 0"/>
    </visual>
  </link>
  <gazebo reference="left_finger[0]/flexible_joint_twist_from_2_to_distal">
    <implicitSpringDamper>1</implicitSpringDamper>
  </gazebo>
  <joint name="left_finger[0]/flexible_joint_twist_from_2_to_distal" type="revolute">
    <parent link="left_finger[0]/flexible_link_hidden_between_2_and_distal_link"/>
    <child link="left_finger[0]/distal_link"/>
    <origin xyz="0 0 0"/>
    <axis xyz="0 0 1"/>
    <limit effort="1000.0" lower="0.0" upper="1.57" velocity="0.5"/>
  </joint>
  <link name="left_finger[1]/flexible_link_1">
    <inertial>
      <mass value="0.00058"/>
      <!-- gazebo -> cad mapping
           x -> y
           y -> z
           z -> x
      -->
      <origin rpy="-1.57 -1.57 0" xyz="0 0 0"/>
      <inertia ixx="8.8101e-8" ixy="0" ixz="0.0" iyy="4.09812e-08" iyz="0.0" izz="5.31842e-08"/>
    </inertial>
    <collision>
      <geometry>
        <box size=".014 0.00792 .006"/>
      </geometry>
      <origin rpy="1.57 0 0" xyz="0 0 0"/>
    </collision>
    <visual>
      <geometry>
        <box size=".014 0.00792 .006"/>
      </geometry>
      <origin rpy="1.57 0 0" xyz="0 0 0"/>
      <material name="darkgray">
        <color rgba="0.2 0.2 0.2 1"/>
      </material>
    </visual>
  </link>
  <link name="left_finger[1]/flexible_link_2">
    <inertial>
      <mass value="0.00058"/>
      <!-- gazebo -> cad mapping
           x -> y
           y -> z
           z -> x
      -->
      <origin rpy="-1.57 -1.57 0" xyz="0 0 0"/>
      <inertia ixx="8.8101e-8" ixy="0" ixz="0.0" iyy="4.09812e-08" iyz="0.0" izz="5.31842e-08"/>
    </inertial>
    <collision>
      <geometry>
        <box size=".014 0.00792 .006"/>
      </geometry>
      <origin rpy="1.57 0 0" xyz="0 0 0"/>
    </collision>
    <visual>
      <geometry>
        <box size=".014 0.00792 .006"/>
      </geometry>
      <origin rpy="1.57 0 0" xyz="0 0 0"/>
      <material name="darkgray">
        <color rgba="0.2 0.2 0.2 1"/>
      </material>
    </visual>
  </link>
  <!-- only up to flex_joint_steps
  <xacro:flex_link side="${side}" finger_id="1" link_id="3"/>
  <xacro:flex_link side="${side}" finger_id="1" link_id="4"/>
  <xacro:flex_link side="${side}" finger_id="1" link_id="5"/>
  <xacro:flex_link side="${side}" finger_id="1" link_id="6"/>
  <xacro:flex_link side="${side}" finger_id="1" link_id="7"/>
  <xacro:flex_link side="${side}" finger_id="1" link_id="8"/>
  <xacro:flex_link side="${side}" finger_id="1" link_id="9"/>
  -->
  <gazebo reference="left_finger[1]/flexible_joint_flex_from_1_to_2">
    <implicitSpringDamper>1</implicitSpringDamper>
  </gazebo>
  <joint name="left_finger[1]/flexible_joint_flex_from_1_to_2" type="revolute">
    <parent link="left_finger[1]/flexible_link_1"/>
    <child link="left_finger[1]/flexible_link_hidden_between_1_and_2"/>
    <origin xyz="0 0 0.008"/>
    <axis xyz="-1 0 0"/>
    <limit effort="1000.0" lower="0.0" upper="1.57" velocity="0.5"/>
  </joint>
  <link name="left_finger[1]/flexible_link_hidden_between_1_and_2">
    <inertial>
      <mass value="0.00058"/>
      <!-- gazebo -> cad mapping
           x -> y
           y -> z
           z -> x
      -->
      <origin rpy="-1.57 -1.57 0" xyz="0 0 0"/>
      <inertia ixx="8.8101e-8" ixy="0" ixz="0.0" iyy="4.09812e-08" iyz="0.0" izz="5.31842e-08"/>
    </inertial>
    <collision>
      <geometry>
        <box size="0 0 0"/>
      </geometry>
      <origin rpy="0 0 0" xyz="0 0 0"/>
    </collision>
    <visual>
      <geometry>
        <box size="0 0 0"/>
      </geometry>
      <origin rpy="0 0 0" xyz="0 0 0"/>
    </visual>
  </link>
  <gazebo reference="left_finger[1]/flexible_joint_twist_from_1_to_2">
    <implicitSpringDamper>1</implicitSpringDamper>
  </gazebo>
  <joint name="left_finger[1]/flexible_joint_twist_from_1_to_2" type="revolute">
    <parent link="left_finger[1]/flexible_link_hidden_between_1_and_2"/>
    <child link="left_finger[1]/flexible_link_2"/>
    <origin xyz="0 0 0"/>
    <axis xyz="0 0 1"/>
    <limit effort="1000.0" lower="0.0" upper="1.57" velocity="0.5"/>
  </joint>
  <!-- only up to flex_joint_steps
  <xacro:flex_joint side="${side}" finger_id="1" link_from="2" link_to="3"/>
  <xacro:flex_joint side="${side}" finger_id="1" link_from="3" link_to="4"/>
  <xacro:flex_joint side="${side}" finger_id="1" link_from="4" link_to="5"/>
  <xacro:flex_joint side="${side}" finger_id="1" link_from="5" link_to="6"/>
  <xacro:flex_joint side="${side}" finger_id="1" link_from="6" link_to="7"/>
  <xacro:flex_joint side="${side}" finger_id="1" link_from="7" link_to="8"/>
  <xacro:flex_joint side="${side}" finger_id="1" link_from="8" link_to="9"/>
  -->
  <!-- make a connection between proximal to flexible-->
  <gazebo reference="left_finger[1]/flexible_joint_flex_from_proximal_to_1">
    <implicitSpringDamper>1</implicitSpringDamper>
  </gazebo>
  <joint name="left_finger[1]/flexible_joint_flex_from_proximal_to_1" type="revolute">
    <parent link="left_finger[1]/proximal_link"/>
    <child link="left_finger[1]/flexible_link_hidden_between_proximal_link_and_1"/>
    <origin xyz="0 0 0.065"/>
    <axis xyz="-1 0 0"/>
    <limit effort="1000.0" lower="0.0" upper="1.57" velocity="0.5"/>
  </joint>
  <link name="left_finger[1]/flexible_link_hidden_between_proximal_link_and_1">
    <inertial>
      <!-- <mass value="${0.0029 / 19}"/> -->
      <mass value="0.00058"/>
      <!-- gazebo -> cad mapping
           x -> y
           y -> z
           z -> x
      -->
      <origin rpy="-1.57 -1.57 0" xyz="0 0 0"/>
      <inertia ixx="8.8101e-8" ixy="0" ixz="0.0" iyy="4.09812e-08" iyz="0.0" izz="5.31842e-08"/>
    </inertial>
    <collision>
      <geometry>
        <box size="0 0 0"/>
      </geometry>
      <origin rpy="0 0 0" xyz="0 0 0"/>
    </collision>
    <visual>
      <geometry>
        <box size="0 0 0"/>
      </geometry>
      <origin rpy="0 0 0" xyz="0 0 0"/>
    </visual>
  </link>
  <gazebo reference="left_finger[1]/flexible_joint_twist_from_proximal_to_1">
    <implicitSpringDamper>1</implicitSpringDamper>
  </gazebo>
  <joint name="left_finger[1]/flexible_joint_twist_from_proximal_to_1" type="revolute">
    <parent link="left_finger[1]/flexible_link_hidden_between_proximal_link_and_1"/>
    <child link="left_finger[1]/flexible_link_1"/>
    <origin xyz="0 0 0"/>
    <axis xyz="0 0 1"/>
    <limit effort="1000.0" lower="0.0" upper="1.57" velocity="0.5"/>
  </joint>
  <!-- make a connection between flexible to distal-->
  <gazebo reference="left_finger[1]/flexible_joint_flex_from_2_to_distal">
    <implicitSpringDamper>1</implicitSpringDamper>
  </gazebo>
  <joint name="left_finger[1]/flexible_joint_flex_from_2_to_distal" type="revolute">
    <parent link="left_finger[1]/flexible_link_2"/>
    <child link="left_finger[1]/flexible_link_hidden_between_2_and_distal_link"/>
    <origin xyz="0 0 0.005"/>
    <axis xyz="-1 0 0"/>
    <limit effort="1000.0" lower="0.0" upper="1.57" velocity="0.5"/>
  </joint>
  <link name="left_finger[1]/flexible_link_hidden_between_2_and_distal_link">
    <inertial>
      <mass value="0.00058"/>
      <!-- gazebo -> cad mapping
           x -> y
           y -> z
           z -> x
      -->
      <origin rpy="-1.57 -1.57 0" xyz="0 0 0"/>
      <inertia ixx="8.8101e-8" ixy="0" ixz="0.0" iyy="4.09812e-08" iyz="0.0" izz="5.31842e-08"/>
    </inertial>
    <collision>
      <geometry>
        <box size="0 0 0"/>
      </geometry>
      <origin rpy="0 0 0" xyz="0 0 0"/>
    </collision>
    <visual>
      <geometry>
        <box size="0 0 0"/>
      </geometry>
      <origin rpy="0 0 0" xyz="0 0 0"/>
    </visual>
  </link>
  <gazebo reference="left_finger[1]/flexible_joint_twist_from_2_to_distal">
    <implicitSpringDamper>1</implicitSpringDamper>
  </gazebo>
  <joint name="left_finger[1]/flexible_joint_twist_from_2_to_distal" type="revolute">
    <parent link="left_finger[1]/flexible_link_hidden_between_2_and_distal_link"/>
    <child link="left_finger[1]/distal_link"/>
    <origin xyz="0 0 0"/>
    <axis xyz="0 0 1"/>
    <limit effort="1000.0" lower="0.0" upper="1.57" velocity="0.5"/>
  </joint>
  <link name="left_finger[2]/flexible_link_1">
    <inertial>
      <mass value="0.00058"/>
      <!-- gazebo -> cad mapping
           x -> y
           y -> z
           z -> x
      -->
      <origin rpy="-1.57 -1.57 0" xyz="0 0 0"/>
      <inertia ixx="8.8101e-8" ixy="0" ixz="0.0" iyy="4.09812e-08" iyz="0.0" izz="5.31842e-08"/>
    </inertial>
    <collision>
      <geometry>
        <box size=".014 0.00792 .006"/>
      </geometry>
      <origin rpy="1.57 0 0" xyz="0 0 0"/>
    </collision>
    <visual>
      <geometry>
        <box size=".014 0.00792 .006"/>
      </geometry>
      <origin rpy="1.57 0 0" xyz="0 0 0"/>
      <material name="darkgray">
        <color rgba="0.2 0.2 0.2 1"/>
      </material>
    </visual>
  </link>
  <link name="left_finger[2]/flexible_link_2">
    <inertial>
      <mass value="0.00058"/>
      <!-- gazebo -> cad mapping
           x -> y
           y -> z
           z -> x
      -->
      <origin rpy="-1.57 -1.57 0" xyz="0 0 0"/>
      <inertia ixx="8.8101e-8" ixy="0" ixz="0.0" iyy="4.09812e-08" iyz="0.0" izz="5.31842e-08"/>
    </inertial>
    <collision>
      <geometry>
        <box size=".014 0.00792 .006"/>
      </geometry>
      <origin rpy="1.57 0 0" xyz="0 0 0"/>
    </collision>
    <visual>
      <geometry>
        <box size=".014 0.00792 .006"/>
      </geometry>
      <origin rpy="1.57 0 0" xyz="0 0 0"/>
      <material name="darkgray">
        <color rgba="0.2 0.2 0.2 1"/>
      </material>
    </visual>
  </link>
  <!-- only up to flex_joint_steps
  <xacro:flex_link side="${side}" finger_id="2" link_id="3"/>
  <xacro:flex_link side="${side}" finger_id="2" link_id="4"/>
  <xacro:flex_link side="${side}" finger_id="2" link_id="5"/>
  <xacro:flex_link side="${side}" finger_id="2" link_id="6"/>
  <xacro:flex_link side="${side}" finger_id="2" link_id="7"/>
  <xacro:flex_link side="${side}" finger_id="2" link_id="8"/>
  <xacro:flex_link side="${side}" finger_id="2" link_id="9"/>
  -->
  <gazebo reference="left_finger[2]/flexible_joint_flex_from_1_to_2">
    <implicitSpringDamper>1</implicitSpringDamper>
  </gazebo>
  <joint name="left_finger[2]/flexible_joint_flex_from_1_to_2" type="revolute">
    <parent link="left_finger[2]/flexible_link_1"/>
    <child link="left_finger[2]/flexible_link_hidden_between_1_and_2"/>
    <origin xyz="0 0 0.008"/>
    <axis xyz="-1 0 0"/>
    <limit effort="1000.0" lower="0.0" upper="1.57" velocity="0.5"/>
  </joint>
  <link name="left_finger[2]/flexible_link_hidden_between_1_and_2">
    <inertial>
      <mass value="0.00058"/>
      <!-- gazebo -> cad mapping
           x -> y
           y -> z
           z -> x
      -->
      <origin rpy="-1.57 -1.57 0" xyz="0 0 0"/>
      <inertia ixx="8.8101e-8" ixy="0" ixz="0.0" iyy="4.09812e-08" iyz="0.0" izz="5.31842e-08"/>
    </inertial>
    <collision>
      <geometry>
        <box size="0 0 0"/>
      </geometry>
      <origin rpy="0 0 0" xyz="0 0 0"/>
    </collision>
    <visual>
      <geometry>
        <box size="0 0 0"/>
      </geometry>
      <origin rpy="0 0 0" xyz="0 0 0"/>
    </visual>
  </link>
  <gazebo reference="left_finger[2]/flexible_joint_twist_from_1_to_2">
    <implicitSpringDamper>1</implicitSpringDamper>
  </gazebo>
  <joint name="left_finger[2]/flexible_joint_twist_from_1_to_2" type="revolute">
    <parent link="left_finger[2]/flexible_link_hidden_between_1_and_2"/>
    <child link="left_finger[2]/flexible_link_2"/>
    <origin xyz="0 0 0"/>
    <axis xyz="0 0 1"/>
    <limit effort="1000.0" lower="0.0" upper="1.57" velocity="0.5"/>
  </joint>
  <!-- only up to flex_joint_steps
  <xacro:flex_joint side="${side}" finger_id="2" link_from="2" link_to="3"/>
  <xacro:flex_joint side="${side}" finger_id="2" link_from="3" link_to="4"/>
  <xacro:flex_joint side="${side}" finger_id="2" link_from="4" link_to="5"/>
  <xacro:flex_joint side="${side}" finger_id="2" link_from="5" link_to="6"/>
  <xacro:flex_joint side="${side}" finger_id="2" link_from="6" link_to="7"/>
  <xacro:flex_joint side="${side}" finger_id="2" link_from="7" link_to="8"/>
  <xacro:flex_joint side="${side}" finger_id="2" link_from="8" link_to="9"/>
  -->
  <!-- make a connection between proximal to flexible-->
  <gazebo reference="left_finger[2]/flexible_joint_flex_from_proximal_to_1">
    <implicitSpringDamper>1</implicitSpringDamper>
  </gazebo>
  <joint name="left_finger[2]/flexible_joint_flex_from_proximal_to_1" type="revolute">
    <parent link="left_finger[2]/proximal_link"/>
    <child link="left_finger[2]/flexible_link_hidden_between_proximal_link_and_1"/>
    <origin xyz="0 0 0.065"/>
    <axis xyz="-1 0 0"/>
    <limit effort="1000.0" lower="0.0" upper="1.57" velocity="0.5"/>
  </joint>
  <link name="left_finger[2]/flexible_link_hidden_between_proximal_link_and_1">
    <inertial>
      <!-- <mass value="${0.0029 / 19}"/> -->
      <mass value="0.00058"/>
      <!-- gazebo -> cad mapping
           x -> y
           y -> z
           z -> x
      -->
      <origin rpy="-1.57 -1.57 0" xyz="0 0 0"/>
      <inertia ixx="8.8101e-8" ixy="0" ixz="0.0" iyy="4.09812e-08" iyz="0.0" izz="5.31842e-08"/>
    </inertial>
    <collision>
      <geometry>
        <box size="0 0 0"/>
      </geometry>
      <origin rpy="0 0 0" xyz="0 0 0"/>
    </collision>
    <visual>
      <geometry>
        <box size="0 0 0"/>
      </geometry>
      <origin rpy="0 0 0" xyz="0 0 0"/>
    </visual>
  </link>
  <gazebo reference="left_finger[2]/flexible_joint_twist_from_proximal_to_1">
    <implicitSpringDamper>1</implicitSpringDamper>
  </gazebo>
  <joint name="left_finger[2]/flexible_joint_twist_from_proximal_to_1" type="revolute">
    <parent link="left_finger[2]/flexible_link_hidden_between_proximal_link_and_1"/>
    <child link="left_finger[2]/flexible_link_1"/>
    <origin xyz="0 0 0"/>
    <axis xyz="0 0 1"/>
    <limit effort="1000.0" lower="0.0" upper="1.57" velocity="0.5"/>
  </joint>
  <!-- make a connection between flexible to distal-->
  <gazebo reference="left_finger[2]/flexible_joint_flex_from_2_to_distal">
    <implicitSpringDamper>1</implicitSpringDamper>
  </gazebo>
  <joint name="left_finger[2]/flexible_joint_flex_from_2_to_distal" type="revolute">
    <parent link="left_finger[2]/flexible_link_2"/>
    <child link="left_finger[2]/flexible_link_hidden_between_2_and_distal_link"/>
    <origin xyz="0 0 0.005"/>
    <axis xyz="-1 0 0"/>
    <limit effort="1000.0" lower="0.0" upper="1.57" velocity="0.5"/>
  </joint>
  <link name="left_finger[2]/flexible_link_hidden_between_2_and_distal_link">
    <inertial>
      <mass value="0.00058"/>
      <!-- gazebo -> cad mapping
           x -> y
           y -> z
           z -> x
      -->
      <origin rpy="-1.57 -1.57 0" xyz="0 0 0"/>
      <inertia ixx="8.8101e-8" ixy="0" ixz="0.0" iyy="4.09812e-08" iyz="0.0" izz="5.31842e-08"/>
    </inertial>
    <collision>
      <geometry>
        <box size="0 0 0"/>
      </geometry>
      <origin rpy="0 0 0" xyz="0 0 0"/>
    </collision>
    <visual>
      <geometry>
        <box size="0 0 0"/>
      </geometry>
      <origin rpy="0 0 0" xyz="0 0 0"/>
    </visual>
  </link>
  <gazebo reference="left_finger[2]/flexible_joint_twist_from_2_to_distal">
    <implicitSpringDamper>1</implicitSpringDamper>
  </gazebo>
  <joint name="left_finger[2]/flexible_joint_twist_from_2_to_distal" type="revolute">
    <parent link="left_finger[2]/flexible_link_hidden_between_2_and_distal_link"/>
    <child link="left_finger[2]/distal_link"/>
    <origin xyz="0 0 0"/>
    <axis xyz="0 0 1"/>
    <limit effort="1000.0" lower="0.0" upper="1.57" velocity="0.5"/>
  </joint>
  <!-- joint attaching parent link to irobot hand -->
  <joint name="left_irobot_hand_joint" type="fixed">
    <origin rpy="0 0 0" xyz="0 0 1.0"/>
    <parent link="base"/>
    <child link="left_base_link"/>
  </joint>
  <link name="left_base_link">
    <inertial>
      <!-- needs update -->
      <mass value="1.305"/>
      <origin xyz="0 0 0"/>
      <inertia ixx="0.00125" ixy="0.0" ixz="0.0" iyy="0.00125" iyz="0.0" izz="0.0002"/>
    </inertial>
    <collision name="collision1">
      <origin rpy="0 0 0" xyz="0 0.02 0.045"/>
      <geometry>
        <box size="0.114 0.1 0.075"/>
      </geometry>
    </collision>
    <collision name="collision2">
      <origin rpy="0 0 0" xyz="0 -0.02 0.045"/>
      <geometry>
        <cylinder length="0.075" radius="0.0448"/>
      </geometry>
    </collision>
    <visual>
      <geometry>
        <mesh filename="package://irobot_hand_description/meshes/palm.stl"/>
      </geometry>
      <material name="darkgray">
        <color rgba="0.2 0.2 0.2 1"/>
      </material>
      <origin rpy="0 0 0" xyz="0 -0.038 -0.023"/>
    </visual>
  </link>
  <link name="left_finger[0]/base_rotation_link">
    <inertial>
      <!-- needs update -->
      <mass value="0.05"/>
      <origin xyz="0 0 0"/>
      <inertia ixx="0.0000125" ixy="0.0" ixz="0.0" iyy="0.0000125" iyz="0.0" izz="0.000002"/>
    </inertial>
    <collision name="collision_1">
      <origin rpy="0 0 0" xyz="0 0 -.0025"/>
      <geometry>
        <cylinder length="0.0145" radius="0.025"/>
      </geometry>
    </collision>
    <collision name="collision_2">
      <origin rpy="0 0 0" xyz="0 0 -.0104"/>
      <geometry>
        <cylinder length="0.0145" radius="0.0165"/>
      </geometry>
    </collision>
    <collision name="collision_3">
      <origin rpy="1.5707 0 1.5707" xyz="0 0 .0135"/>
      <geometry>
        <cylinder length="0.02" radius="0.002"/>
      </geometry>
    </collision>
    <collision name="collision_4">
      <origin rpy="1.5707 0 1.5707" xyz="0.013 0 .0135"/>
      <geometry>
        <cylinder length="0.008" radius="0.009"/>
      </geometry>
    </collision>
    <collision name="collision_5">
      <origin rpy="1.5707 0 1.5707" xyz="-0.013 0 .0135"/>
      <geometry>
        <cylinder length="0.008" radius="0.009"/>
      </geometry>
    </collision>
    <visual>
      <geometry>
        <mesh filename="package://irobot_hand_description/meshes/finger_base.stl"/>
      </geometry>
      <material name="darkgray">
        <color rgba="0.2 0.2 0.2 1"/>
      </material>
      <origin rpy="1.57 0 0" xyz="0 0 0"/>
    </visual>
  </link>
  <link name="left_finger[0]/proximal_link">
    <inertial>
      <mass value="0.0288"/>
      <!-- gazebo -> cad coordinate mapping
             x -> -y
             y -> -z
             z -> x
        -->
      <origin rpy="1.57 -1.57 0" xyz="-0.002630 0.002396 0.021770"/>
      <inertia ixx="2.420689e-6" ixy="-1.449042e-6" ixz="-7.74579e-7" iyy="1.196202e-6" iyz="1.90704e-7" izz="1.2736461e-6"/>
    </inertial>
    <collision name="collision1">
      <origin rpy="0 0 0" xyz="0 0.0028 0.033"/>
      <geometry>
        <box size="0.018 0.019 0.055"/>
      </geometry>
    </collision>
    <collision name="collision2">
      <origin rpy="0 1.5707 0" xyz="0 0 0"/>
      <geometry>
        <cylinder length="0.018" radius="0.009"/>
      </geometry>
    </collision>
    <visual>
      <geometry>
        <mesh filename="package://irobot_hand_description/meshes/finger_proximal.stl"/>
      </geometry>
      <material name="green">
        <color rgba="0.1 0.6 0.1 1"/>
      </material>
      <origin rpy="1.57 -1.57 0" xyz="0 0 0"/>
    </visual>
  </link>
  <link name="left_finger[0]/proximal_accelerometer"/>
  <joint name="left_finger[0]/proximal_link_to_accelerometer" type="fixed">
    <parent link="left_finger[0]/proximal_link"/>
    <child link="left_finger[0]/proximal_accelerometer"/>
    <origin rpy="1.57 0 0" xyz="0 0 0.05"/>
  </joint>
  <link name="left_finger[0]/distal_link">
    <inertial>
      <mass value="0.0133"/>
      <!-- gazebo -> cad mapping
             x -> -x
             y -> y
             z -> -z
        -->
      <origin rpy="0 3.14 0" xyz="-0.000066 -0.003142 0.016633"/>
      <inertia ixx="1.624140e-6" ixy="5.60e-10" ixz="1.33e-10" iyy="1.717885e-6" iyz="-1.19970e-7" izz="5.60221e-7"/>
    </inertial>
    <collision name="collision">
      <origin rpy="3.141590 0.001593              3.141590" xyz="0 0.0024 0.01476"/>
      <geometry>
        <box size="0.0175 0.02011 0.03195"/>
      </geometry>
    </collision>
    <collision name="collision_tip">
      <origin rpy="1.57078 0.001593 1.57078" xyz="0 0.004 0.03"/>
      <geometry>
        <cylinder length="0.0175" radius="0.00848"/>
      </geometry>
    </collision>
    <collision name="collision_nail">
      <origin rpy="1.57078 0.001593 0" xyz="0 -0.00529 0.032"/>
      <geometry>
        <cylinder length="0.00159" radius="0.00750"/>
      </geometry>
    </collision>
    <visual>
      <geometry>
        <mesh filename="package://irobot_hand_description/meshes/finger_distal.stl"/>
      </geometry>
      <material name="green">
        <color rgba="0.1 0.6 0.1 1"/>
      </material>
      <origin rpy="0 3.14 0" xyz="0 0 0"/>
    </visual>
  </link>
  <link name="left_finger[0]/distal_accelerometer"/>
  <joint name="left_finger[0]/distal_link_to_accelerometer" type="fixed">
    <parent link="left_finger[0]/distal_link"/>
    <child link="left_finger[0]/distal_accelerometer"/>
    <origin rpy="1.57 0 0" xyz="0 0 0.02"/>
  </joint>
  <link name="left_finger[1]/base_rotation_link">
    <inertial>
      <mass value="0.05"/>
      <origin xyz="0 0 0"/>
      <inertia ixx="0.0000125" ixy="0.0" ixz="0.0" iyy="0.0000125" iyz="0.0" izz="0.000002"/>
    </inertial>
    <collision name="collision_1">
      <origin rpy="0 0 0" xyz="0 0 -.0025"/>
      <geometry>
        <cylinder length="0.0145" radius="0.025"/>
      </geometry>
    </collision>
    <collision name="collision_2">
      <origin rpy="0 0 0" xyz="0 0 -.0104"/>
      <geometry>
        <cylinder length="0.0145" radius="0.0165"/>
      </geometry>
    </collision>
    <collision name="collision_3">
      <origin rpy="1.5707 0 1.5707" xyz="0 0 .0135"/>
      <geometry>
        <cylinder length="0.02" radius="0.002"/>
      </geometry>
    </collision>
    <collision name="collision_4">
      <origin rpy="1.5707 0 1.5707" xyz="0.013 0 .0135"/>
      <geometry>
        <cylinder length="0.008" radius="0.009"/>
      </geometry>
    </collision>
    <collision name="collision_5">
      <origin rpy="1.5707 0 1.5707" xyz="-0.013 0 .0135"/>
      <geometry>
        <cylinder length="0.008" radius="0.009"/>
      </geometry>
    </collision>
    <visual>
      <geometry>
        <mesh filename="package://irobot_hand_description/meshes/finger_base.stl"/>
      </geometry>
      <material name="darkgray">
        <color rgba="0.2 0.2 0.2 1"/>
      </material>
      <origin rpy="1.57 0 0" xyz="0 0 0"/>
    </visual>
  </link>
  <link name="left_finger[1]/proximal_link">
    <inertial>
      <mass value="0.0288"/>
      <!-- gazebo -> cad coordinate mapping
             x -> -y
             y -> -z
             z -> x
        -->
      <origin rpy="1.57 -1.57 0" xyz="-0.002630 0.002396 0.021770"/>
      <inertia ixx="2.420689e-6" ixy="-1.449042e-6" ixz="-7.74579e-7" iyy="1.196202e-6" iyz="1.90704e-7" izz="1.2736461e-6"/>
    </inertial>
    <collision name="collision1">
      <origin rpy="0 0 0" xyz="0 0.0028 0.033"/>
      <geometry>
        <box size="0.018 0.019 0.055"/>
      </geometry>
    </collision>
    <collision name="collision2">
      <origin rpy="0 1.5707 0" xyz="0 0 0"/>
      <geometry>
        <cylinder length="0.018" radius="0.009"/>
      </geometry>
    </collision>
    <visual>
      <geometry>
        <mesh filename="package://irobot_hand_description/meshes/finger_proximal.stl"/>
      </geometry>
      <material name="green">
        <color rgba="0.1 0.6 0.1 1"/>
      </material>
      <origin rpy="1.57 -1.57 0" xyz="0 0 0"/>
    </visual>
  </link>
  <link name="left_finger[1]/proximal_accelerometer"/>
  <joint name="left_finger[1]/proximal_link_to_accelerometer" type="fixed">
    <parent link="left_finger[1]/proximal_link"/>
    <child link="left_finger[1]/proximal_accelerometer"/>
    <origin rpy="1.57 0 0" xyz="0 0 0.05"/>
  </joint>
  <link name="left_finger[1]/distal_link">
    <inertial>
      <mass value="0.0133"/>
      <!-- gazebo -> cad mapping
             x -> -x
             y -> y
             z -> -z
        -->
      <origin rpy="0 3.14 0" xyz="-0.000066 -0.003142 0.016633"/>
      <inertia ixx="1.624140e-6" ixy="5.60e-10" ixz="1.33e-10" iyy="1.717885e-6" iyz="-1.19970e-7" izz="5.60221e-7"/>
    </inertial>
    <collision name="collision">
      <origin rpy="3.141590 0.001593              3.141590" xyz="0 0.0024 0.01476"/>
      <geometry>
        <box size="0.0175 0.02011 0.03195"/>
      </geometry>
    </collision>
    <collision name="collision_tip">
      <origin rpy="1.57078 0.001593 1.57078" xyz="0 0.004 0.03"/>
      <geometry>
        <cylinder length="0.0175" radius="0.00848"/>
      </geometry>
    </collision>
    <collision name="collision_nail">
      <origin rpy="1.57078 0.001593 0" xyz="0 -0.00529 0.032"/>
      <geometry>
        <cylinder length="0.00159" radius="0.00750"/>
      </geometry>
    </collision>
    <visual>
      <geometry>
        <mesh filename="package://irobot_hand_description/meshes/finger_distal.stl"/>
      </geometry>
      <material name="green">
        <color rgba="0.1 0.6 0.1 1"/>
      </material>
      <origin rpy="0 3.14 0" xyz="0 0 0"/>
    </visual>
  </link>
  <link name="left_finger[1]/distal_accelerometer"/>
  <joint name="left_finger[1]/distal_link_to_accelerometer" type="fixed">
    <parent link="left_finger[1]/distal_link"/>
    <child link="left_finger[1]/distal_accelerometer"/>
    <origin rpy="1.57 0 0" xyz="0 0 0.02"/>
  </joint>
  <link name="left_finger[2]/proximal_link">
    <inertial>
      <mass value="0.0288"/>
      <!-- gazebo -> cad coordinate mapping
             x -> -y
             y -> -z
             z -> x
        -->
      <origin rpy="1.57 -1.57 0" xyz="-0.002630 0.002396 0.021770"/>
      <inertia ixx="2.420689e-6" ixy="-1.449042e-6" ixz="-7.74579e-7" iyy="1.196202e-6" iyz="1.90704e-7" izz="1.2736461e-6"/>
    </inertial>
    <collision name="collision1">
      <origin rpy="0 0 0" xyz="0 0.0028 0.033"/>
      <geometry>
        <box size="0.018 0.019 0.055"/>
      </geometry>
    </collision>
    <collision name="collision2">
      <origin rpy="0 1.5707 0" xyz="0 0 0"/>
      <geometry>
        <cylinder length="0.018" radius="0.009"/>
      </geometry>
    </collision>
    <visual>
      <geometry>
        <mesh filename="package://irobot_hand_description/meshes/finger_proximal.stl"/>
      </geometry>
      <material name="green">
        <color rgba="0.1 0.6 0.1 1"/>
      </material>
      <origin rpy="1.57 -1.57 0" xyz="0 0 0"/>
    </visual>
  </link>
  <link name="left_finger[2]/proximal_accelerometer"/>
  <joint name="left_finger[2]/proximal_link_to_accelerometer" type="fixed">
    <parent link="left_finger[2]/proximal_link"/>
    <child link="left_finger[2]/proximal_accelerometer"/>
    <origin rpy="1.57 0 0" xyz="0 0 0.05"/>
  </joint>
  <link name="left_finger[2]/distal_link">
    <inertial>
      <mass value="0.0133"/>
      <!-- gazebo -> cad mapping
             x -> -x
             y -> y
             z -> -z
        -->
      <origin rpy="0 3.14 0" xyz="-0.000066 -0.003142 0.016633"/>
      <inertia ixx="1.624140e-6" ixy="5.60e-10" ixz="1.33e-10" iyy="1.717885e-6" iyz="-1.19970e-7" izz="5.60221e-7"/>
    </inertial>
    <collision name="collision">
      <origin rpy="3.141590 0.001593              3.141590" xyz="0 0.0024 0.01476"/>
      <geometry>
        <box size="0.0175 0.02011 0.03195"/>
      </geometry>
    </collision>
    <collision name="collision_tip">
      <origin rpy="1.57078 0.001593 1.57078" xyz="0 0.004 0.03"/>
      <geometry>
        <cylinder length="0.0175" radius="0.00848"/>
      </geometry>
    </collision>
    <collision name="collision_nail">
      <origin rpy="1.57078 0.001593 0" xyz="0 -0.00529 0.032"/>
      <geometry>
        <cylinder length="0.00159" radius="0.00750"/>
      </geometry>
    </collision>
    <visual>
      <geometry>
        <mesh filename="package://irobot_hand_description/meshes/finger_distal.stl"/>
      </geometry>
      <material name="green">
        <color rgba="0.1 0.6 0.1 1"/>
      </material>
      <origin rpy="0 3.14 0" xyz="0 0 0"/>
    </visual>
  </link>
  <link name="left_finger[2]/distal_accelerometer"/>
  <joint name="left_finger[2]/distal_link_to_accelerometer" type="fixed">
    <parent link="left_finger[2]/distal_link"/>
    <child link="left_finger[2]/distal_accelerometer"/>
    <origin rpy="1.57 0 0" xyz="0 0 0.02"/>
  </joint>
  <gazebo reference="left_finger[0]/joint_base_rotation">
    <implicitSpringDamper>1</implicitSpringDamper>
  </gazebo>
  <joint name="left_finger[0]/joint_base_rotation" type="revolute">
    <parent link="left_base_link"/>
    <child link="left_finger[0]/base_rotation_link"/>
    <origin rpy="0 0 0" xyz="0.03075 0.038 0.069477"/>
    <axis xyz="0 0 -1"/>
    <limit effort="1000.0" lower="0.0" upper="1.57" velocity="0.5"/>
  </joint>
  <gazebo reference="left_finger[0]/joint_base">
    <implicitSpringDamper>1</implicitSpringDamper>
  </gazebo>
  <joint name="left_finger[0]/joint_base" type="revolute">
    <parent link="left_finger[0]/base_rotation_link"/>
    <child link="left_finger[0]/proximal_link"/>
    <origin rpy="1.57 0 -3.14" xyz="0 0 0.0135"/>
    <axis xyz="-1 0 0"/>
    <limit effort="1000.0" lower="0.0" upper="2.7475" velocity="0.5"/>
  </joint>
  <gazebo reference="left_finger[1]/joint_base_rotation">
    <implicitSpringDamper>1</implicitSpringDamper>
  </gazebo>
  <joint name="left_finger[1]/joint_base_rotation" type="revolute">
    <parent link="left_base_link"/>
    <child link="left_finger[1]/base_rotation_link"/>
    <origin rpy="0 0 0" xyz="-0.03075 0.038 0.069477"/>
    <axis xyz="0 0 1"/>
    <limit effort="1000.0" lower="0.0" upper="1.57" velocity="0.5"/>
  </joint>
  <gazebo>
    <joint name="left_spread_gearbox" type="gearbox">
      <parent>left_finger[0]/base_rotation_link</parent>
      <child>left_finger[1]/base_rotation_link</child>
      <!-- ${side}_base_link got lumped into ${parent},
           so we need to fix parser_urdf.cc to propagate name
           changes into this extension before switching this
           to use ${side_base_link}. -->
      <gearbox_reference_body>base</gearbox_reference_body>
      <gearbox_ratio>1.0</gearbox_ratio>
      <axis>
        <!-- yikes, what coordinate frame is this specified in?
             0 0 1 causes NaNs. 0 1 0 works, but unsure why yet.-->
        <xyz>0 1 0</xyz>
      </axis>
      <axis2>
        <!-- yikes, what coordinate frame is this specified in?
             0 0 1 causes NaNs. 0 1 0 works, but unsure why yet.-->
        <xyz>0 1 0</xyz>
      </axis2>
    </joint>
  </gazebo>
  <gazebo reference="left_finger[1]/joint_base">
    <implicitSpringDamper>1</implicitSpringDamper>
  </gazebo>
  <joint name="left_finger[1]/joint_base" type="revolute">
    <parent link="left_finger[1]/base_rotation_link"/>
    <child link="left_finger[1]/proximal_link"/>
    <origin rpy="1.57 0 -3.14" xyz="0 0 0.0135"/>
    <axis xyz="-1 0 0"/>
    <limit effort="1000.0" lower="0.0" upper="2.7475" velocity="0.5"/>
  </joint>
  <gazebo reference="left_finger[2]/joint_base">
    <implicitSpringDamper>1</implicitSpringDamper>
  </gazebo>
  <joint name="left_finger[2]/joint_base" type="revolute">
    <parent link="left_base_link"/>
    <child link="left_finger[2]/proximal_link"/>
    <origin rpy="1.57 0 0" xyz="0 -0.038 0.082755"/>
    <axis xyz="-1 0 0"/>
    <limit effort="1000.0" lower="0.0" upper="2.7475" velocity="0.5"/>
  </joint>
</robot>

